Workbook

Sheet Master_Items
A1: Item ID | B1: Category | C1: Sub-Category | D1: Item Name | E1: Brand | F1: Size | G1: Unit | H1: Par Level | I1: Reorder Qty | J1: Active | K1: Pour Size (oz) | L1: Notes
A2: I-0001 | B2: Liquor | C2: Whiskey | D2: Jameson Irish | E2: Jameson | F2: 1L | G2: Bottle | H2: 8 | I2: 4 | J2: =IF(ISNUMBER(MATCH(B2,Inventory_Tracking!$B$2:$B$1000,0)),"No","Yes") | K2: 2
A3: I-0002 | B3: Liquor | C3: Whiskey | D3: Four Walls | E3: Four | F3: 750 | G3: Bottle | H3: 8 | I3: 4 | J3: =IF(ISNUMBER(MATCH(B3,Inventory_Tracking!$B$2:$B$1000,0)),"No","Yes") | K3: 2
A4: I-0003 | B4: Liquor | C4: Whiskey | D4: Crown Royal Apple | E4: Crown Royal | F4: 750ml | G4: Bottle | H4: 6 | I4: 3 | J4: =IF(ISNUMBER(MATCH(B4,Inventory_Tracking!$B$2:$B$1000,0)),"No","Yes") | K4: 2
A5: I-0004 | B5: Liquor | C5: Whiskey | D5: Crown Royal Peach | E5: Crown Royal | F5: 750ml | G5: Bottle | H5: 6 | I5: 3 | J5: =IF(ISNUMBER(MATCH(B5,Inventory_Tracking!$B$2:$B$1000,0)),"No","Yes") | K5: 2
A6: I-0005 | B6: Liquor | C6: Whiskey | D6: Crown Royal Vanilla | E6: Crown Royal | F6: 750ml | G6: Bottle | H6: 4 | I6: 2 | J6: =IF(ISNUMBER(MATCH(B6,Inventory_Tracking!$B$2:$B$1000,0)),"No","Yes") | K6: 2
A7: I-0006 | B7: Liquor | C7: Whiskey | D7: Crown Royal Canadian Whisky | E7: Crown Royal | F7: 750ml | G7: Bottle | H7: 6 | I7: 3 | J7: =IF(ISNUMBER(MATCH(B7,Inventory_Tracking!$B$2:$B$1000,0)),"No","Yes") | K7: 2
A8: I-0007 | B8: Liquor | C8: Whiskey | D8: Texas Ranger Peach | E8: Texas Ranger | F8: 750ml | G8: Bottle | H8: 4 | I8: 2 | J8: =IF(ISNUMBER(MATCH(B8,Inventory_Tracking!$B$2:$B$1000,0)),"No","Yes") | K8: 2
A9: I-0008 | B9: Liquor | C9: Whiskey | D9: Texas Ranger Coconut | E9: Texas Ranger | F9: 750ml | G9: Bottle | H9: 4 | I9: 2 | J9: =IF(ISNUMBER(MATCH(B9,Inventory_Tracking!$B$2:$B$1000,0)),"No","Yes") | K9: 2
A10: I-0009 | B10: Liquor | C10: Whiskey | D10: Texas Ranger Peanut Butter | E10: Texas Ranger | F10: 750ml | G10: Bottle | H10: 4 | I10: 2 | J10: =IF(ISNUMBER(MATCH(B10,Inventory_Tracking!$B$2:$B$1000,0)),"No","Yes") | K10: 2
A11: I-0010 | B11: Liquor | C11: Whiskey | D11: SagaMore Rye | E11: SagaMore | F11: 750ml | G11: Bottle | H11: 5 | I11: 2 | J11: =IF(ISNUMBER(MATCH(B11,Inventory_Tracking!$B$2:$B$1000,0)),"No","Yes") | K11: 2
A12: I-0011 | B12: Liquor | C12: Whiskey | D12: Bulleit Rye Whiskey | E12: Bulleit | F12: 750ml | G12: Bottle | H12: 5 | I12: 2 | J12: =IF(ISNUMBER(MATCH(B12,Inventory_Tracking!$B$2:$B$1000,0)),"No","Yes") | K12: 2
A13: I-0012 | B13: Liquor | C13: Whiskey | D13: Dewar’s White Label | E13: Dewar’s | F13: 1L | G13: Bottle | H13: 4 | I13: 2 | J13: =IF(ISNUMBER(MATCH(B13,Inventory_Tracking!$B$2:$B$1000,0)),"No","Yes") | K13: 2
A14: I-0013 | B14: Liquor | C14: Whiskey | D14: Buchanan’s 12 | E14: Buchanan’s | F14: 1L | G14: Bottle | H14: 4 | I14: 2 | J14: =IF(ISNUMBER(MATCH(B14,Inventory_Tracking!$B$2:$B$1000,0)),"No","Yes") | K14: 2
A15: I-0014 | B15: Liquor | C15: Whiskey | D15: Wild Turkey 101 | E15: Wild Turkey | F15: 750ml | G15: Bottle | H15: 4 | I15: 2 | J15: =IF(ISNUMBER(MATCH(B15,Inventory_Tracking!$B$2:$B$1000,0)),"No","Yes") | K15: 2
... A55: I-0054 | B55: Liquor | C55: Vodka | D55: Smirnoff Red,White&Merry | E55: Smirnoff | F55: 750ml | G55: Bottle | H55: 4 | I55: 2 | J55: =IF(ISNUMBER(MATCH(B55,Inventory_Tracking!$B$2:$B$1000,0)),"No","Yes") | K55: 2
A56: I-0055 | B56: Liquor | C56: Vodka | D56: Dry Well Mountain | E56: DryWell | F56: 1L | G56: Bottle | J56: =IF(ISNUMBER(MATCH(B56,Inventory_Tracking!$B$2:$B$1000,0)),"No","Yes")
A57: I-0056 | B57: Liquor | C57: Vodka | D57: Ketel One | E57: Ketel One | F57: 1L | G57: Bottle | H57: 4 | I57: 2 | J57: =IF(ISNUMBER(MATCH(B57,Inventory_Tracking!$B$2:$B$1000,0)),"No","Yes") | K57: 2
A58: I-0057 | B58: Liquor | C58: Vodka | D58: Wheatley Vodka | E58: Wheatley | F58: 750ml | G58: Bottle | H58: 3 | I58: 1 | J58: =IF(ISNUMBER(MATCH(B58,Inventory_Tracking!$B$2:$B$1000,0)),"No","Yes") | K58: 2
A59: I-0058 | B59: Liquor | C59: Gin | D59: Taaka | E59: Taaka | F59: 1L | G59: Bottle | H59: 4 | I59: 2 | J59: =IF(ISNUMBER(MATCH(B59,Inventory_Tracking!$B$2:$B$1000,0)),"No","Yes") | K59: 2
A60: I-0059 | B60: Liquor | C60: Gin | D60: Hendrick’s | E60: Hendrick’s | F60: 750ml | G60: Bottle | H60: 4 | I60: 2 | J60: =IF(ISNUMBER(MATCH(B60,Inventory_Tracking!$B$2:$B$1000,0)),"No","Yes") | K60: 2
A61: I-0060 | B61: Liquor | C61: Gin | D61: Tanqueray | E61: Tanqueray | F61: 750ml | G61: Bottle | H61: 4 | I61: 2 | J61: =IF(ISNUMBER(MATCH(B61,Inventory_Tracking!$B$2:$B$1000,0)),"No","Yes") | K61: 2
A62: I-0061 | B62: Liquor | C62: Gin | D62: Bombay Sapphire | E62: Bombay Sapphire | F62: 750ml | G62: Bottle | H62: 4 | I62: 2 | J62: =IF(ISNUMBER(MATCH(B62,Inventory_Tracking!$B$2:$B$1000,0)),"No","Yes") | K62: 2
A63: I-0062 | B63: Liquor | C63: Rum | D63: Bacardi Light | E63: Bacardi | F63: 1L | G63: Bottle | H63: 6 | I63: 3 | J63: =IF(ISNUMBER(MATCH(B63,Inventory_Tracking!$B$2:$B$1000,0)),"No","Yes") | K63: 2
A64: I-0063 | B64: Liquor | C64: Rum | D64: Castillo Light | E64: Castillo | F64: 1L | G64: Bottle | H64: 4 | I64: 2 | J64: =IF(ISNUMBER(MATCH(B64,Inventory_Tracking!$B$2:$B$1000,0)),"No","Yes") | K64: 2
A65: I-0064 | B65: Liquor | C65: Rum | D65: Ron Corina Coconut | E65: Ron Corina | F65: 750ml | G65: Bottle | H65: 3 | I65: 1 | J65: =IF(ISNUMBER(MATCH(B65,Inventory_Tracking!$B$2:$B$1000,0)),"No","Yes") | K65: 2
A66: I-0065 | B66: Liquor | C66: Rum | D66: Captain Morgan Spiced | E66: Captain Morgan | F66: 1L | G66: Bottle | H66: 5 | I66: 2 | J66: =IF(ISNUMBER(MATCH(B66,Inventory_Tracking!$B$2:$B$1000,0)),"No","Yes") | K66: 2
A67: I-0066 | B67: Liquor | C67: Rum | D67: Captain Morgan Original | E67: Captain Morgan | F67: 1L | G67: Bottle | H67: 5 | I67: 2 | J67: =IF(ISNUMBER(MATCH(B67,Inventory_Tracking!$B$2:$B$1000,0)),"No","Yes") | K67: 2
A68: I-0067 | B68: Liquor | C68: Rum | D68: Malibu Coconut | E68: Malibu | F68: 750ml | G68: Bottle | H68: 4 | I68: 2 | J68: =IF(ISNUMBER(MATCH(B68,Inventory_Tracking!$B$2:$B$1000,0)),"No","Yes") | K68: 2
... A74: I-0073 | B74: Liquor | C74: Rum | D74: Parrot Bay | E74: Parrot Bay | F74: 750ml | G74: Bottle | H74: 3 | I74: 1 | J74: =IF(ISNUMBER(MATCH(B74,Inventory_Tracking!$B$2:$B$1000,0)),"No","Yes") | K74: 2
A75: I-0074 | B75: Liquor | C75: Tequila | D75: Lalo | E75: Lalo | F75: 1L | G75: Bottle | J75: =IF(ISNUMBER(MATCH(B75,Inventory_Tracking!$B$2:$B$1000,0)),"No","Yes")
A76: I-0075 | B76: Liquor | C76: Tequila | D76: 1800 Blanco | E76: 1800 | F76: 1L | G76: Bottle | H76: 6 | I76: 3 | J76: =IF(ISNUMBER(MATCH(B76,Inventory_Tracking!$B$2:$B$1000,0)),"No","Yes") | K76: 2
A77: I-0076 | B77: Liquor | C77: Tequila | D77: Torada Silver | E77: Torada | F77: 1L | G77: Bottle | H77: 6 | I77: 3 | J77: =IF(ISNUMBER(MATCH(B77,Inventory_Tracking!$B$2:$B$1000,0)),"No","Yes") | K77: 2
A78: I-0077 | B78: Liquor | C78: Tequila | D78: JaJa Reposado | E78: Jaja | F78: 750ml | G78: Bottle | H78: 6 | I78: 3 | J78: =IF(ISNUMBER(MATCH(B78,Inventory_Tracking!$B$2:$B$1000,0)),"No","Yes") | K78: 2
A79: I-0078 | B79: Liquor | C79: Tequila | D79: JaJa Blanco | E79: Jaja | F79: 750ml | G79: Bottle | H79: 6 | I79: 3 | J79: =IF(ISNUMBER(MATCH(B79,Inventory_Tracking!$B$2:$B$1000,0)),"No","Yes") | K79: 2
A80: I-0079 | B80: Liquor | C80: Tequila | D80: Casamigos Blanco | E80: Casamigos | F80: 750ml | G80: Bottle | H80: 5 | I80: 2 | J80: =IF(ISNUMBER(MATCH(B80,Inventory_Tracking!$B$2:$B$1000,0)),"No","Yes") | K80: 2
A81: I-0080 | B81: Liquor | C81: Tequila | D81: Maestro Dobel Diamante | E81: Maestro | F81: 750ml | G81: Bottle | H81: 5 | I81: 2 | J81: =IF(ISNUMBER(MATCH(B81,Inventory_Tracking!$B$2:$B$1000,0)),"No","Yes") | K81: 2
A82: I-0081 | B82: Liquor | C82: Tequila | D82: Casamigos Reposado | E82: Casamigos | F82: 1L | G82: Bottle | H82: 4 | I82: 2 | J82: =IF(ISNUMBER(MATCH(B82,Inventory_Tracking!$B$2:$B$1000,0)),"No","Yes") | K82: 2
A83: I-0082 | B83: Liquor | C83: Tequila | D83: Espolòn Reposado | E83: Espolòn | F83: 750ml | G83: Bottle | H83: 5 | I83: 2 | J83: =IF(ISNUMBER(MATCH(B83,Inventory_Tracking!$B$2:$B$1000,0)),"No","Yes") | K83: 2
A84: I-0083 | B84: Liquor | C84: Tequila | D84: Espolòn Blanco | E84: Espolòn | F84: 750ml | G84: Bottle | H84: 5 | I84: 2 | J84: =IF(ISNUMBER(MATCH(B84,Inventory_Tracking!$B$2:$B$1000,0)),"No","Yes") | K84: 2
...

Sheet Vendors_Pricing
A1: Item Name | B1: Vendor | C1: Vendor SKU | D1: Pack Size | E1: Unit Cost | F1: Last Cost | G1: Last Updated | H1: Preferred Vendor | I1: Notes
I2: =IF(E2=MINIFS(E:E, A:A, A2), "Yes", "")
I3: =IF(E3=MINIFS(E:E, A:A, A3), "Yes", "")
I4: =IF(E4=MINIFS(E:E, A:A, A4), "Yes", "")
I5: =IF(E5=MINIFS(E:E, A:A, A5), "Yes", "")
I6: =IF(E6=MINIFS(E:E, A:A, A6), "Yes", "")
I7: =IF(E7=MINIFS(E:E, A:A, A7), "Yes", "")
I8: =IF(E8=MINIFS(E:E, A:A, A8), "Yes", "")
I9: =IF(E9=MINIFS(E:E, A:A, A9), "Yes", "")
I10: =IF(E10=MINIFS(E:E, A:A, A10), "Yes", "")
I11: =IF(E11=MINIFS(E:E, A:A, A11), "Yes", "")
I12: =IF(E12=MINIFS(E:E, A:A, A12), "Yes", "")
I13: =IF(E13=MINIFS(E:E, A:A, A13), "Yes", "")
... I527: =IF(E527=MINIFS(E:E, A:A, A527), "Yes", "")

Sheet Inventory_Tracking
A1: Date | B1: Item Name | C1: Opening Qty | D1: Purchased | E1: Used | F1: Closing Qty | G1: Unit Cost | H1: Inventory Value | I1: Below Par | J1: Notes | K1: Closing Qty
A2: 01/19/2026 | B2: Glenlivet Reserve | C2: 4 | F2: =C2 + D2 - E2 | H2: =K2*G2 | I2: =IF(F2 <= IFERROR(VLOOKUP(B2, Master_Items!C:H, 6, FALSE), 0), "REORDER", "") | K2: =C2+D2
B3: Captain Morgan Spiced | C3: 2 | F3: =C3 + D3 - E3 | H3: =K3*G3 | I3: =IF(F3 <= IFERROR(VLOOKUP(B3, Master_Items!C:H, 6, FALSE), 0), "REORDER", "") | K3: =C3+D3
B4: Fireball Cinnamon | C4: 5 | F4: =C4 + D4 - E4 | H4: =K4*G4 | I4: =IF(F4 <= IFERROR(VLOOKUP(B4, Master_Items!C:H, 6, FALSE), 0), "REORDER", "") | K4: =C4+D4
B5: Bacardi Light | C5: 3 | F5: =C5 + D5 - E5 | H5: =K5*G5 | I5: =IF(F5 <= IFERROR(VLOOKUP(B5, Master_Items!C:H, 6, FALSE), 0), "REORDER", "") | K5: =C5+D5
B6: Glenlivet 12 | C6: 1 | F6: =C6 + D6 - E6 | H6: =K6*G6 | I6: =IF(F6 <= IFERROR(VLOOKUP(B6, Master_Items!C:H, 6, FALSE), 0), "REORDER", "") | K6: =C6+D6
B7: Traveller Blend N9 40 | C7: 1 | F7: =C7 + D7 - E7 | H7: =K7*G7 | I7: =IF(F7 <= IFERROR(VLOOKUP(B7, Master_Items!C:H, 6, FALSE), 0), "REORDER", "") | K7: =C7+D7
B8: Dewar’s White Label | C8: 1 | F8: =C8 + D8 - E8 | H8: =K8*G8 | I8: =IF(F8 <= IFERROR(VLOOKUP(B8, Master_Items!C:H, 6, FALSE), 0), "REORDER", "") | K8: =C8+D8
B9: Jack Daniel’s Tennessee Black Berry | C9: 1 | F9: =C9 + D9 - E9 | H9: =K9*G9 | I9: =IF(F9 <= IFERROR(VLOOKUP(B9, Master_Items!C:H, 6, FALSE), 0), "REORDER", "") | K9: =C9+D9
B10: Smirnoff Red,White&Merry | C10: 1 | F10: =C10 + D10 - E10 | H10: =K10*G10 | I10: =IF(F10 <= IFERROR(VLOOKUP(B10, Master_Items!C:H, 6, FALSE), 0), "REORDER", "") | K10: =C10+D10
B11: Buchanan’s 12 | C11: 2 | F11: =C11 + D11 - E11 | H11: =K11*G11 | I11: =IF(F11 <= IFERROR(VLOOKUP(B11, Master_Items!C:H, 6, FALSE), 0), "REORDER", "") | K11: =C11+D11
B12: Macallan 12 | C12: 1 | F12: =C12 + D12 - E12 | H12: =K12*G12 | I12: =IF(F12 <= IFERROR(VLOOKUP(B12, Master_Items!C:H, 6, FALSE), 0), "REORDER", "") | K12: =C12+D12
B13: Macallan 15 | C13: 1 | F13: =C13 + D13 - E13 | H13: =K13*G13 | I13: =IF(F13 <= IFERROR(VLOOKUP(B13, Master_Items!C:H, 6, FALSE), 0), "REORDER", "") | K13: =C13+D13
B14: Glenfiddich 15 | C14: 1 | F14: =C14 + D14 - E14 | H14: =K14*G14 | I14: =IF(F14 <= IFERROR(VLOOKUP(B14, Master_Items!C:H, 6, FALSE), 0), "REORDER", "") | K14: =C14+D14
... B102: Prosecco | C102: 14 | F102: =C102 + D102 - E102 | H102: =K102*G102 | I102: =IF(F102 <= IFERROR(VLOOKUP(B102, Master_Items!C:H, 6, FALSE), 0), "REORDER", "") | K102: =C102+D102
B103: Topo Chico Hard Seltzer | C103: 34 | H103: =K103*G103 | K103: =C103+D103
B104: Rose’s Grenadine | C104: 7 | F104: =C104 + D104 - E104 | H104: =K104*G104 | I104: =IF(F104 <= IFERROR(VLOOKUP(B104, Master_Items!C:H, 6, FALSE), 0), "REORDER", "") | K104: =C104+D104
B105: Rose’s Lime Juice | C105: 2 | F105: =C105 + D105 - E105 | H105: =K105*G105 | I105: =IF(F105 <= IFERROR(VLOOKUP(B105, Master_Items!C:H, 6, FALSE), 0), "REORDER", "") | K105: =C105+D105
B106: Monin Cucumber | C106: 4 | F106: =C106 + D106 - E106 | H106: =K106*G106 | I106: =IF(F106 <= IFERROR(VLOOKUP(B106, Master_Items!C:H, 6, FALSE), 0), "REORDER", "") | K106: =C106+D106
B107: Pineapple Juice | C107: 2 | F107: =C107 + D107 - E107 | H107: =K107*G107 | I107: =IF(F107 <= IFERROR(VLOOKUP(B107, Master_Items!C:H, 6, FALSE), 0), "REORDER", "") | K107: =C107+D107
B108: Bar Syrup | C108: 3 | F108: =C108 + D108 - E108 | H108: =K108*G108 | I108: =IF(F108 <= IFERROR(VLOOKUP(B108, Master_Items!C:H, 6, FALSE), 0), "REORDER", "") | K108: =C108+D108
B109: Pina Colada Mix | C109: 4 | F109: =C109 + D109 - E109 | H109: =K109*G109 | I109: =IF(F109 <= IFERROR(VLOOKUP(B109, Master_Items!C:H, 6, FALSE), 0), "REORDER", "") | K109: =C109+D109
B110: Strawberry Puree | C110: 5 | F110: =C110 + D110 - E110 | H110: =K110*G110 | I110: =IF(F110 <= IFERROR(VLOOKUP(B110, Master_Items!C:H, 6, FALSE), 0), "REORDER", "") | K110: =C110+D110
B111: Passion Fruit Puree | C111: 2 | F111: =C111 + D111 - E111 | H111: =K111*G111 | I111: =IF(F111 <= IFERROR(VLOOKUP(B111, Master_Items!C:H, 6, FALSE), 0), "REORDER", "") | K111: =C111+D111
B112: Agave Syrup | C112: 3 | F112: =C112 + D112 - E112 | H112: =K112*G112 | I112: =IF(F112 <= IFERROR(VLOOKUP(B112, Master_Items!C:H, 6, FALSE), 0), "REORDER", "") | K112: =C112+D112
B113: Lemon Juice | C113: 3 | F113: =C113 + D113 - E113 | H113: =K113*G113 | I113: =IF(F113 <= IFERROR(VLOOKUP(B113, Master_Items!C:H, 6, FALSE), 0), "REORDER", "") | K113: =C113+D113
B114: Lime Juice | C114: 1 | F114: =C114 + D114 - E114 | H114: =K114*G114 | I114: =IF(F114 <= IFERROR(VLOOKUP(B114, Master_Items!C:H, 6, FALSE), 0), "REORDER", "") | K114: =C114+D114
F115: =C115 + D115 - E115 | H115: =K115*G115 | I115: =IF(F115 <= IFERROR(VLOOKUP(B115, Master_Items!C:H, 6, FALSE), 0), "REORDER", "") | K115: =C115+D115
F116: =C116 + D116 - E116 | H116: =K116*G116 | I116: =IF(F116 <= IFERROR(VLOOKUP(B116, Master_Items!C:H, 6, FALSE), 0), "REORDER", "") | K116: =C116+D116
F117: =C117 + D117 - E117 | H117: =K117*G117 | I117: =IF(F117 <= IFERROR(VLOOKUP(B117, Master_Items!C:H, 6, FALSE), 0), "REORDER", "") | K117: =C117+D117
F118: =C118 + D118 - E118 | H118: =K118*G118 | I118: =IF(F118 <= IFERROR(VLOOKUP(B118, Master_Items!C:H, 6, FALSE), 0), "REORDER", "") | K118: =C118+D118
F119: =C119 + D119 - E119 | H119: =K119*G119 | I119: =IF(F119 <= IFERROR(VLOOKUP(B119, Master_Items!C:H, 6, FALSE), 0), "REORDER", "") | K119: =C119+D119
F120: =C120 + D120 - E120 | H120: =K120*G120 | I120: =IF(F120 <= IFERROR(VLOOKUP(B120, Master_Items!C:H, 6, FALSE), 0), "REORDER", "") | K120: =C120+D120
F121: =C121 + D121 - E121 | H121: =K121*G121 | I121: =IF(F121 <= IFERROR(VLOOKUP(B121, Master_Items!C:H, 6, FALSE), 0), "REORDER", "") | K121: =C121+D121
F122: =C122 + D122 - E122 | H122: =K122*G122 | I122: =IF(F122 <= IFERROR(VLOOKUP(B122, Master_Items!C:H, 6, FALSE), 0), "REORDER", "") | K122: =C122+D122
F123: =C123 + D123 - E123 | H123: =K123*G123 | I123: =IF(F123 <= IFERROR(VLOOKUP(B123, Master_Items!C:H, 6, FALSE), 0), "REORDER", "") | K123: =C123+D123
F124: =C124 + D124 - E124 | H124: =K124*G124 | I124: =IF(F124 <= IFERROR(VLOOKUP(B124, Master_Items!C:H, 6, FALSE), 0), "REORDER", "") | K124: =C124+D124
F125: =C125 + D125 - E125 | H125: =K125*G125 | I125: =IF(F125 <= IFERROR(VLOOKUP(B125, Master_Items!C:H, 6, FALSE), 0), "REORDER", "") | K125: =C125+D125
F126: =C126 + D126 - E126 | H126: =K126*G126 | I126: =IF(F126 <= IFERROR(VLOOKUP(B126, Master_Items!C:H, 6, FALSE), 0), "REORDER", "") | K126: =C126+D126
... F582: =C582 + D582 - E582 | H582: =K582*G582 | I582: =IF(F582 <= IFERROR(VLOOKUP(B582, Master_Items!C:H, 6, FALSE), 0), "REORDER", "") | K582: =C582+D582
...

Sheet Purchases_Log
A1: Date | B1: Vendor | C1: Item Name | D1: Qty Purchased | E1: Unit Cost | F1: Total Cost | G1: Invoice # | H1: Paid? | I1: Notes
E2: =IFERROR(__xludf.DUMMYFUNCTION("IFERROR( VLOOKUP( C2, FILTER(Vendors_Pricing!A:E, Vendors_Pricing!H:H=""Yes""), 5, FALSE ), """" ) "),"") | F2: =D2 * E2
E3: =IFERROR(__xludf.DUMMYFUNCTION("IFERROR( VLOOKUP( C3, FILTER(Vendors_Pricing!A:E, Vendors_Pricing!H:H=""Yes""), 5, FALSE ), """" ) "),"") | F3: =D3 * E3
E4: =IFERROR(__xludf.DUMMYFUNCTION("IFERROR( VLOOKUP( C4, FILTER(Vendors_Pricing!A:E, Vendors_Pricing!H:H=""Yes""), 5, FALSE ), """" ) "),"") | F4: =D4 * E4
E5: =IFERROR(__xludf.DUMMYFUNCTION("IFERROR( VLOOKUP( C5, FILTER(Vendors_Pricing!A:E, Vendors_Pricing!H:H=""Yes""), 5, FALSE ), """" ) "),"") | F5: =D5 * E5
E6: =IFERROR(__xludf.DUMMYFUNCTION("IFERROR( VLOOKUP( C6, FILTER(Vendors_Pricing!A:E, Vendors_Pricing!H:H=""Yes""), 5, FALSE ), """" ) "),"") | F6: =D6 * E6
E7: =IFERROR(__xludf.DUMMYFUNCTION("IFERROR( VLOOKUP( C7, FILTER(Vendors_Pricing!A:E, Vendors_Pricing!H:H=""Yes""), 5, FALSE ), """" ) "),"") | F7: =D7 * E7
E8: =IFERROR(__xludf.DUMMYFUNCTION("IFERROR( VLOOKUP( C8, FILTER(Vendors_Pricing!A:E, Vendors_Pricing!H:H=""Yes""), 5, FALSE ), """" ) "),"") | F8: =D8 * E8
E9: =IFERROR(__xludf.DUMMYFUNCTION("IFERROR( VLOOKUP( C9, FILTER(Vendors_Pricing!A:E, Vendors_Pricing!H:H=""Yes""), 5, FALSE ), """" ) "),"") | F9: =D9 * E9
E10: =IFERROR(__xludf.DUMMYFUNCTION("IFERROR( VLOOKUP( C10, FILTER(Vendors_Pricing!A:E, Vendors_Pricing!H:H=""Yes""), 5, FALSE ), """" ) "),"") | F10: =D10 * E10
E11: =IFERROR(__xludf.DUMMYFUNCTION("IFERROR( VLOOKUP( C11, FILTER(Vendors_Pricing!A:E, Vendors_Pricing!H:H=""Yes""), 5, FALSE ), """" ) "),"") | F11: =D11 * E11
E12: =IFERROR(__xludf.DUMMYFUNCTION("IFERROR( VLOOKUP( C12, FILTER(Vendors_Pricing!A:E, Vendors_Pricing!H:H=""Yes""), 5, FALSE ), """" ) "),"") | F12: =D12 * E12
E13: =IFERROR(__xludf.DUMMYFUNCTION("IFERROR( VLOOKUP( C13, FILTER(Vendors_Pricing!A:E, Vendors_Pricing!H:H=""Yes""), 5, FALSE ), """" ) "),"") | F13: =D13 * E13
E14: =IFERROR(__xludf.DUMMYFUNCTION("IFERROR( VLOOKUP( C14, FILTER(Vendors_Pricing!A:E, Vendors_Pricing!H:H=""Yes""), 5, FALSE ), """" ) "),"") | F14: =D14 * E14
E15: =IFERROR(__xludf.DUMMYFUNCTION("IFERROR( VLOOKUP( C15, FILTER(Vendors_Pricing!A:E, Vendors_Pricing!H:H=""Yes""), 5, FALSE ), """" ) "),"") | F15: =D15 * E15
E16: =IFERROR(__xludf.DUMMYFUNCTION("IFERROR( VLOOKUP( C16, FILTER(Vendors_Pricing!A:E, Vendors_Pricing!H:H=""Yes""), 5, FALSE ), """" ) "),"") | F16: =D16 * E16
E17: =IFERROR(__xludf.DUMMYFUNCTION("IFERROR( VLOOKUP( C17, FILTER(Vendors_Pricing!A:E, Vendors_Pricing!H:H=""Yes""), 5, FALSE ), """" ) "),"") | F17: =D17 * E17
E18: =IFERROR(__xludf.DUMMYFUNCTION("IFERROR( VLOOKUP( C18, FILTER(Vendors_Pricing!A:E, Vendors_Pricing!H:H=""Yes""), 5, FALSE ), """" ) "),"") | F18: =D18 * E18
E19: =IFERROR(__xludf.DUMMYFUNCTION("IFERROR( VLOOKUP( C19, FILTER(Vendors_Pricing!A:E, Vendors_Pricing!H:H=""Yes""), 5, FALSE ), """" ) "),"") | F19: =D19 * E19
E20: =IFERROR(__xludf.DUMMYFUNCTION("IFERROR( VLOOKUP( C20, FILTER(Vendors_Pricing!A:E, Vendors_Pricing!H:H=""Yes""), 5, FALSE ), """" ) "),"") | F20: =D20 * E20
E21: =IFERROR(__xludf.DUMMYFUNCTION("IFERROR( VLOOKUP( C21, FILTER(Vendors_Pricing!A:E, Vendors_Pricing!H:H=""Yes""), 5, FALSE ), """" ) "),"") | F21: =D21 * E21
E22: =IFERROR(__xludf.DUMMYFUNCTION("IFERROR( VLOOKUP( C22, FILTER(Vendors_Pricing!A:E, Vendors_Pricing!H:H=""Yes""), 5, FALSE ), """" ) "),"") | F22: =D22 * E22
E23: =IFERROR(__xludf.DUMMYFUNCTION("IFERROR( VLOOKUP( C23, FILTER(Vendors_Pricing!A:E, Vendors_Pricing!H:H=""Yes""), 5, FALSE ), """" ) "),"") | F23: =D23 * E23
E24: =IFERROR(__xludf.DUMMYFUNCTION("IFERROR( VLOOKUP( C24, FILTER(Vendors_Pricing!A:E, Vendors_Pricing!H:H=""Yes""), 5, FALSE ), """" ) "),"") | F24: =D24 * E24
E25: =IFERROR(__xludf.DUMMYFUNCTION("IFERROR( VLOOKUP( C25, FILTER(Vendors_Pricing!A:E, Vendors_Pricing!H:H=""Yes""), 5, FALSE ), """" ) "),"") | F25: =D25 * E25
E26: =IFERROR(__xludf.DUMMYFUNCTION("IFERROR( VLOOKUP( C26, FILTER(Vendors_Pricing!A:E, Vendors_Pricing!H:H=""Yes""), 5, FALSE ), """" ) "),"") | F26: =D26 * E26
E27: =IFERROR(__xludf.DUMMYFUNCTION("IFERROR( VLOOKUP( C27, FILTER(Vendors_Pricing!A:E, Vendors_Pricing!H:H=""Yes""), 5, FALSE ), """" ) "),"") | F27: =D27 * E27
E28: =IFERROR(__xludf.DUMMYFUNCTION("IFERROR( VLOOKUP( C28, FILTER(Vendors_Pricing!A:E, Vendors_Pricing!H:H=""Yes""), 5, FALSE ), """" ) "),"") | F28: =D28 * E28
E29: =IFERROR(__xludf.DUMMYFUNCTION("IFERROR( VLOOKUP( C29, FILTER(Vendors_Pricing!A:E, Vendors_Pricing!H:H=""Yes""), 5, FALSE ), """" ) "),"") | F29: =D29 * E29
E30: =IFERROR(__xludf.DUMMYFUNCTION("IFERROR( VLOOKUP( C30, FILTER(Vendors_Pricing!A:E, Vendors_Pricing!H:H=""Yes""), 5, FALSE ), """" ) "),"") | F30: =D30 * E30
E31: =IFERROR(__xludf.DUMMYFUNCTION("IFERROR( VLOOKUP( C31, FILTER(Vendors_Pricing!A:E, Vendors_Pricing!H:H=""Yes""), 5, FALSE ), """" ) "),"") | F31: =D31 * E31
E32: =IFERROR(__xludf.DUMMYFUNCTION("IFERROR( VLOOKUP( C32, FILTER(Vendors_Pricing!A:E, Vendors_Pricing!H:H=""Yes""), 5, FALSE ), """" ) "),"") | F32: =D32 * E32
E33: =IFERROR(__xludf.DUMMYFUNCTION("IFERROR( VLOOKUP( C33, FILTER(Vendors_Pricing!A:E, Vendors_Pricing!H:H=""Yes""), 5, FALSE ), """" ) "),"") | F33: =D33 * E33
E34: =IFERROR(__xludf.DUMMYFUNCTION("IFERROR( VLOOKUP( C34, FILTER(Vendors_Pricing!A:E, Vendors_Pricing!H:H=""Yes""), 5, FALSE ), """" ) "),"") | F34: =D34 * E34
E35: =IFERROR(__xludf.DUMMYFUNCTION("IFERROR( VLOOKUP( C35, FILTER(Vendors_Pricing!A:E, Vendors_Pricing!H:H=""Yes""), 5, FALSE ), """" ) "),"") | F35: =D35 * E35
E36: =IFERROR(__xludf.DUMMYFUNCTION("IFERROR( VLOOKUP( C36, FILTER(Vendors_Pricing!A:E, Vendors_Pricing!H:H=""Yes""), 5, FALSE ), """" ) "),"") | F36: =D36 * E36
E37: =IFERROR(__xludf.DUMMYFUNCTION("IFERROR( VLOOKUP( C37, FILTER(Vendors_Pricing!A:E, Vendors_Pricing!H:H=""Yes""), 5, FALSE ), """" ) "),"") | F37: =D37 * E37
E38: =IFERROR(__xludf.DUMMYFUNCTION("IFERROR( VLOOKUP( C38, FILTER(Vendors_Pricing!A:E, Vendors_Pricing!H:H=""Yes""), 5, FALSE ), """" ) "),"") | F38: =D38 * E38
E39: =IFERROR(__xludf.DUMMYFUNCTION("IFERROR( VLOOKUP( C39, FILTER(Vendors_Pricing!A:E, Vendors_Pricing!H:H=""Yes""), 5, FALSE ), """" ) "),"") | F39: =D39 * E39
E40: =IFERROR(__xludf.DUMMYFUNCTION("IFERROR( VLOOKUP( C40, FILTER(Vendors_Pricing!A:E, Vendors_Pricing!H:H=""Yes""), 5, FALSE ), """" ) "),"") | F40: =D40 * E40
...

Sheet Vendors
A1: Vendor Name
A2: Specs
A3: Total Wine
A4: Restaurant Depot
A5: Costco
A6: HEB
A7: Twin Liquors
